Traceback (most recent call last):
  File "/usr/local/var/pyenv/versions/3.8.2/lib/python3.8/site-packages/nbclient/client.py", line 604, in _async_poll_for_reply
    msg = await ensure_async(self.kc.shell_channel.get_msg(timeout=new_timeout))
  File "/usr/local/var/pyenv/versions/3.8.2/lib/python3.8/site-packages/nbclient/util.py", line 85, in ensure_async
    result = await obj
  File "/usr/local/var/pyenv/versions/3.8.2/lib/python3.8/site-packages/jupyter_client/asynchronous/channels.py", line 48, in get_msg
    raise Empty
_queue.Empty

During handling of the above exception, another exception occurred:

Traceback (most recent call last):
  File "/usr/local/var/pyenv/versions/3.8.2/lib/python3.8/site-packages/jupyter_cache/executors/utils.py", line 51, in single_nb_execution
    executenb(
  File "/usr/local/var/pyenv/versions/3.8.2/lib/python3.8/site-packages/nbclient/client.py", line 1082, in execute
    return NotebookClient(nb=nb, resources=resources, km=km, **kwargs).execute()
  File "/usr/local/var/pyenv/versions/3.8.2/lib/python3.8/site-packages/nbclient/util.py", line 74, in wrapped
    return just_run(coro(*args, **kwargs))
  File "/usr/local/var/pyenv/versions/3.8.2/lib/python3.8/site-packages/nbclient/util.py", line 53, in just_run
    return loop.run_until_complete(coro)
  File "/usr/local/var/pyenv/versions/3.8.2/lib/python3.8/asyncio/base_events.py", line 616, in run_until_complete
    return future.result()
  File "/usr/local/var/pyenv/versions/3.8.2/lib/python3.8/site-packages/nbclient/client.py", line 535, in async_execute
    await self.async_execute_cell(
  File "/usr/local/var/pyenv/versions/3.8.2/lib/python3.8/site-packages/nbclient/client.py", line 811, in async_execute_cell
    exec_reply = await self.task_poll_for_reply
  File "/usr/local/var/pyenv/versions/3.8.2/lib/python3.8/site-packages/nbclient/client.py", line 628, in _async_poll_for_reply
    await self._async_handle_timeout(timeout, cell)
  File "/usr/local/var/pyenv/versions/3.8.2/lib/python3.8/site-packages/nbclient/client.py", line 678, in _async_handle_timeout
    raise CellTimeoutError.error_from_timeout_and_cell(
nbclient.exceptions.CellTimeoutError: A cell timed out while it was being executed, after 30 seconds.
The message was: Cell execution timed out.
Here is a preview of the cell contents:
-------------------
['nsweeps = 10^6', 'num_spins = 100', '', 'rng = MersenneTwister(4649)', 's0 = rand(rng, Int8[-1, 1], num_spins)']
...
['    solve!(ss, acc, 1/T, nsweeps, ntherm, niters_meas, rng)', '    E = Meas.mean(acc, "E")', '    E2 = Meas.mean(acc, "E2")', '    push!(C_mc, (E2-E^2)/T^2)', 'end']
-------------------

